Traceback (most recent call last):
  File "/usr/share/miniconda3/envs/runenv/lib/python3.10/site-packages/jupyter_cache/executors/utils.py", line 51, in single_nb_execution
    executenb(
  File "/usr/share/miniconda3/envs/runenv/lib/python3.10/site-packages/nbclient/client.py", line 1204, in execute
    return NotebookClient(nb=nb, resources=resources, km=km, **kwargs).execute()
  File "/usr/share/miniconda3/envs/runenv/lib/python3.10/site-packages/nbclient/util.py", line 84, in wrapped
    return just_run(coro(*args, **kwargs))
  File "/usr/share/miniconda3/envs/runenv/lib/python3.10/site-packages/nbclient/util.py", line 62, in just_run
    return loop.run_until_complete(coro)
  File "/usr/share/miniconda3/envs/runenv/lib/python3.10/asyncio/base_events.py", line 649, in run_until_complete
    return future.result()
  File "/usr/share/miniconda3/envs/runenv/lib/python3.10/site-packages/nbclient/client.py", line 663, in async_execute
    await self.async_execute_cell(
  File "/usr/share/miniconda3/envs/runenv/lib/python3.10/site-packages/nbclient/client.py", line 965, in async_execute_cell
    await self._check_raise_for_error(cell, cell_index, exec_reply)
  File "/usr/share/miniconda3/envs/runenv/lib/python3.10/site-packages/nbclient/client.py", line 862, in _check_raise_for_error
    raise CellExecutionError.from_cell_and_msg(cell, exec_reply_content)
nbclient.exceptions.CellExecutionError: An error occurred while executing the following cell:
------------------
a -= a.mean()
a /= a.std() # Standardize the matrix

a.std(), a.mean()
------------------

[0;31m---------------------------------------------------------------------------[0m
[0;31mUFuncTypeError[0m                            Traceback (most recent call last)
Cell [0;32mIn[69], line 1[0m
[0;32m----> 1[0m a [38;5;241m-[39m[38;5;241m=[39m a[38;5;241m.[39mmean()
[1;32m      2[0m a [38;5;241m/[39m[38;5;241m=[39m a[38;5;241m.[39mstd() [38;5;66;03m# Standardize the matrix[39;00m
[1;32m      4[0m a[38;5;241m.[39mstd(), a[38;5;241m.[39mmean()

[0;31mUFuncTypeError[0m: Cannot cast ufunc 'subtract' output from dtype('float64') to dtype('int64') with casting rule 'same_kind'
UFuncTypeError: Cannot cast ufunc 'subtract' output from dtype('float64') to dtype('int64') with casting rule 'same_kind'

