Traceback (most recent call last):
  File "/usr/share/miniconda3/envs/runenv/lib/python3.13/site-packages/jupyter_core/utils/__init__.py", line 154, in wrapped
    asyncio.get_running_loop()
    ~~~~~~~~~~~~~~~~~~~~~~~~^^
RuntimeError: no running event loop

During handling of the above exception, another exception occurred:

Traceback (most recent call last):
  File "/usr/share/miniconda3/envs/runenv/lib/python3.13/site-packages/jupyter_cache/executors/utils.py", line 58, in single_nb_execution
    executenb(
    ~~~~~~~~~^
        nb,
        ^^^
    ...<4 lines>...
        **kwargs,
        ^^^^^^^^^
    )
    ^
  File "/usr/share/miniconda3/envs/runenv/lib/python3.13/site-packages/nbclient/client.py", line 1319, in execute
    return NotebookClient(nb=nb, resources=resources, km=km, **kwargs).execute()
           ~~~~~~~~~~~~~~~~~~~~~~~~~~~~~~~~~~~~~~~~~~~~~~~~~~~~~~~~~~~~~~~~~~~^^
  File "/usr/share/miniconda3/envs/runenv/lib/python3.13/site-packages/jupyter_core/utils/__init__.py", line 158, in wrapped
    return loop.run_until_complete(inner)
           ~~~~~~~~~~~~~~~~~~~~~~~^^^^^^^
  File "/usr/share/miniconda3/envs/runenv/lib/python3.13/asyncio/base_events.py", line 725, in run_until_complete
    return future.result()
           ~~~~~~~~~~~~~^^
  File "/usr/share/miniconda3/envs/runenv/lib/python3.13/site-packages/nbclient/client.py", line 709, in async_execute
    await self.async_execute_cell(
        cell, index, execution_count=self.code_cells_executed + 1
    )
  File "/usr/share/miniconda3/envs/runenv/lib/python3.13/site-packages/nbclient/client.py", line 1062, in async_execute_cell
    await self._check_raise_for_error(cell, cell_index, exec_reply)
  File "/usr/share/miniconda3/envs/runenv/lib/python3.13/site-packages/nbclient/client.py", line 918, in _check_raise_for_error
    raise CellExecutionError.from_cell_and_msg(cell, exec_reply_content)
nbclient.exceptions.CellExecutionError: An error occurred while executing the following cell:
------------------
from scipy.interpolate import interp2d
x,y = sp.mgrid[0:1:20j,0:1:20j]  #create the grid 20x20
z = np.cos(4*sp.pi*x)*np.sin(4*sp.pi*y) #initialize the field
T1=interp2d(x,y,z,kind='linear') 
T2=interp2d(x,y,z,kind='cubic') 
T3=interp2d(x,y,z,kind='quintic')
------------------


[31m---------------------------------------------------------------------------[39m
[31mKeyError[39m                                  Traceback (most recent call last)
[36mFile [39m[32m/usr/share/miniconda3/envs/runenv/lib/python3.13/site-packages/scipy/__init__.py:137[39m, in [36m__getattr__[39m[34m(name)[39m
[32m    136[39m [38;5;28;01mtry[39;00m:
[32m--> [39m[32m137[39m     [38;5;28;01mreturn[39;00m [38;5;28;43mglobals[39;49m[43m([49m[43m)[49m[43m[[49m[43mname[49m[43m][49m
[32m    138[39m [38;5;28;01mexcept[39;00m [38;5;167;01mKeyError[39;00m:

[31mKeyError[39m: 'mgrid'

During handling of the above exception, another exception occurred:

[31mAttributeError[39m                            Traceback (most recent call last)
[36mCell[39m[36m [39m[32mIn[4][39m[32m, line 2[39m
[32m      1[39m [38;5;28;01mfrom[39;00m[38;5;250m [39m[34;01mscipy[39;00m[34;01m.[39;00m[34;01minterpolate[39;00m[38;5;250m [39m[38;5;28;01mimport[39;00m interp2d
[32m----> [39m[32m2[39m x,y = [43msp[49m[43m.[49m[43mmgrid[49m[[32m0[39m:[32m1[39m:[32m20[39mj,[32m0[39m:[32m1[39m:[32m20[39mj]  [38;5;66;03m#create the grid 20x20[39;00m
[32m      3[39m z = np.cos([32m4[39m*sp.pi*x)*np.sin([32m4[39m*sp.pi*y) [38;5;66;03m#initialize the field[39;00m
[32m      4[39m T1=interp2d(x,y,z,kind=[33m'[39m[33mlinear[39m[33m'[39m) 

[36mFile [39m[32m/usr/share/miniconda3/envs/runenv/lib/python3.13/site-packages/scipy/__init__.py:139[39m, in [36m__getattr__[39m[34m(name)[39m
[32m    137[39m     [38;5;28;01mreturn[39;00m [38;5;28mglobals[39m()[name]
[32m    138[39m [38;5;28;01mexcept[39;00m [38;5;167;01mKeyError[39;00m:
[32m--> [39m[32m139[39m     [38;5;28;01mraise[39;00m [38;5;167;01mAttributeError[39;00m(
[32m    140[39m         [33mf[39m[33m"[39m[33mModule [39m[33m'[39m[33mscipy[39m[33m'[39m[33m has no attribute [39m[33m'[39m[38;5;132;01m{[39;00mname[38;5;132;01m}[39;00m[33m'[39m[33m"[39m
[32m    141[39m     )

[31mAttributeError[39m: Module 'scipy' has no attribute 'mgrid'

