Traceback (most recent call last):
  File "/usr/share/miniconda3/envs/runenv/lib/python3.13/site-packages/jupyter_core/utils/__init__.py", line 154, in wrapped
    asyncio.get_running_loop()
    ~~~~~~~~~~~~~~~~~~~~~~~~^^
RuntimeError: no running event loop

During handling of the above exception, another exception occurred:

Traceback (most recent call last):
  File "/usr/share/miniconda3/envs/runenv/lib/python3.13/site-packages/jupyter_cache/executors/utils.py", line 58, in single_nb_execution
    executenb(
    ~~~~~~~~~^
        nb,
        ^^^
    ...<4 lines>...
        **kwargs,
        ^^^^^^^^^
    )
    ^
  File "/usr/share/miniconda3/envs/runenv/lib/python3.13/site-packages/nbclient/client.py", line 1319, in execute
    return NotebookClient(nb=nb, resources=resources, km=km, **kwargs).execute()
           ~~~~~~~~~~~~~~~~~~~~~~~~~~~~~~~~~~~~~~~~~~~~~~~~~~~~~~~~~~~~~~~~~~~^^
  File "/usr/share/miniconda3/envs/runenv/lib/python3.13/site-packages/jupyter_core/utils/__init__.py", line 158, in wrapped
    return loop.run_until_complete(inner)
           ~~~~~~~~~~~~~~~~~~~~~~~^^^^^^^
  File "/usr/share/miniconda3/envs/runenv/lib/python3.13/asyncio/base_events.py", line 725, in run_until_complete
    return future.result()
           ~~~~~~~~~~~~~^^
  File "/usr/share/miniconda3/envs/runenv/lib/python3.13/site-packages/nbclient/client.py", line 709, in async_execute
    await self.async_execute_cell(
        cell, index, execution_count=self.code_cells_executed + 1
    )
  File "/usr/share/miniconda3/envs/runenv/lib/python3.13/site-packages/nbclient/client.py", line 1062, in async_execute_cell
    await self._check_raise_for_error(cell, cell_index, exec_reply)
  File "/usr/share/miniconda3/envs/runenv/lib/python3.13/site-packages/nbclient/client.py", line 918, in _check_raise_for_error
    raise CellExecutionError.from_cell_and_msg(cell, exec_reply_content)
nbclient.exceptions.CellExecutionError: An error occurred while executing the following cell:
------------------
from sympy.utilities.autowrap import ufuncify
f = ufuncify([x], expr, backend='f2py') 

t = np.linspace(0,4*np.pi,100)
plt.plot(t, f(t));
------------------


[31m---------------------------------------------------------------------------[39m
[31mTypeError[39m                                 Traceback (most recent call last)
[36mFile [39m[32m/usr/share/miniconda3/envs/runenv/lib/python3.13/site-packages/sympy/core/cache.py:72[39m, in [36m__cacheit.<locals>.func_wrapper.<locals>.wrapper[39m[34m(*args, **kwargs)[39m
[32m     71[39m [38;5;28;01mtry[39;00m:
[32m---> [39m[32m72[39m     retval = [43mcfunc[49m[43m([49m[43m*[49m[43margs[49m[43m,[49m[43m [49m[43m*[49m[43m*[49m[43mkwargs[49m[43m)[49m
[32m     73[39m [38;5;28;01mexcept[39;00m [38;5;167;01mTypeError[39;00m [38;5;28;01mas[39;00m e:

[31mTypeError[39m: unhashable type: 'list'

During handling of the above exception, another exception occurred:

[31mTypeError[39m                                 Traceback (most recent call last)
[36mFile [39m[32m/usr/share/miniconda3/envs/runenv/lib/python3.13/site-packages/sympy/core/cache.py:72[39m, in [36m__cacheit.<locals>.func_wrapper.<locals>.wrapper[39m[34m(*args, **kwargs)[39m
[32m     71[39m [38;5;28;01mtry[39;00m:
[32m---> [39m[32m72[39m     retval = [43mcfunc[49m[43m([49m[43m*[49m[43margs[49m[43m,[49m[43m [49m[43m*[49m[43m*[49m[43mkwargs[49m[43m)[49m
[32m     73[39m [38;5;28;01mexcept[39;00m [38;5;167;01mTypeError[39;00m [38;5;28;01mas[39;00m e:

[31mTypeError[39m: unhashable type: 'list'

During handling of the above exception, another exception occurred:

[31mCalledProcessError[39m                        Traceback (most recent call last)
[36mFile [39m[32m/usr/share/miniconda3/envs/runenv/lib/python3.13/site-packages/sympy/utilities/autowrap.py:183[39m, in [36mCodeWrapper._process_files[39m[34m(self, routine)[39m
[32m    182[39m [38;5;28;01mtry[39;00m:
[32m--> [39m[32m183[39m     retoutput = [43mcheck_output[49m[43m([49m[43mcommand[49m[43m,[49m[43m [49m[43mstderr[49m[43m=[49m[43mSTDOUT[49m[43m)[49m
[32m    184[39m [38;5;28;01mexcept[39;00m CalledProcessError [38;5;28;01mas[39;00m e:

[36mFile [39m[32m/usr/share/miniconda3/envs/runenv/lib/python3.13/subprocess.py:472[39m, in [36mcheck_output[39m[34m(timeout, *popenargs, **kwargs)[39m
[32m    470[39m     kwargs[[33m'[39m[33minput[39m[33m'[39m] = empty
[32m--> [39m[32m472[39m [38;5;28;01mreturn[39;00m [43mrun[49m[43m([49m[43m*[49m[43mpopenargs[49m[43m,[49m[43m [49m[43mstdout[49m[43m=[49m[43mPIPE[49m[43m,[49m[43m [49m[43mtimeout[49m[43m=[49m[43mtimeout[49m[43m,[49m[43m [49m[43mcheck[49m[43m=[49m[38;5;28;43;01mTrue[39;49;00m[43m,[49m
[32m    473[39m [43m           [49m[43m*[49m[43m*[49m[43mkwargs[49m[43m)[49m.stdout

[36mFile [39m[32m/usr/share/miniconda3/envs/runenv/lib/python3.13/subprocess.py:577[39m, in [36mrun[39m[34m(input, capture_output, timeout, check, *popenargs, **kwargs)[39m
[32m    576[39m     [38;5;28;01mif[39;00m check [38;5;129;01mand[39;00m retcode:
[32m--> [39m[32m577[39m         [38;5;28;01mraise[39;00m CalledProcessError(retcode, process.args,
[32m    578[39m                                  output=stdout, stderr=stderr)
[32m    579[39m [38;5;28;01mreturn[39;00m CompletedProcess(process.args, retcode, stdout, stderr)

[31mCalledProcessError[39m: Command '['/usr/share/miniconda3/envs/runenv/bin/python', '-c', 'import numpy.f2py as f2py2e;f2py2e.main()', '-c', '-m', 'wrapper_module_0', 'wrapped_code_0.f90']' returned non-zero exit status 1.

During handling of the above exception, another exception occurred:

[31mCodeWrapError[39m                             Traceback (most recent call last)
[36mCell[39m[36m [39m[32mIn[14][39m[32m, line 2[39m
[32m      1[39m [38;5;28;01mfrom[39;00m[38;5;250m [39m[34;01msympy[39;00m[34;01m.[39;00m[34;01mutilities[39;00m[34;01m.[39;00m[34;01mautowrap[39;00m[38;5;250m [39m[38;5;28;01mimport[39;00m ufuncify
[32m----> [39m[32m2[39m f = [43mufuncify[49m[43m([49m[43m[[49m[43mx[49m[43m][49m[43m,[49m[43m [49m[43mexpr[49m[43m,[49m[43m [49m[43mbackend[49m[43m=[49m[33;43m'[39;49m[33;43mf2py[39;49m[33;43m'[39;49m[43m)[49m 
[32m      4[39m t = np.linspace([32m0[39m,[32m4[39m*np.pi,[32m100[39m)
[32m      5[39m plt.plot(t, f(t));

[36mFile [39m[32m/usr/share/miniconda3/envs/runenv/lib/python3.13/site-packages/sympy/core/cache.py:76[39m, in [36m__cacheit.<locals>.func_wrapper.<locals>.wrapper[39m[34m(*args, **kwargs)[39m
[32m     74[39m     [38;5;28;01mif[39;00m [38;5;129;01mnot[39;00m e.args [38;5;129;01mor[39;00m [38;5;129;01mnot[39;00m e.args[[32m0[39m].startswith([33m'[39m[33munhashable type:[39m[33m'[39m):
[32m     75[39m         [38;5;28;01mraise[39;00m
[32m---> [39m[32m76[39m     retval = [43mfunc[49m[43m([49m[43m*[49m[43margs[49m[43m,[49m[43m [49m[43m*[49m[43m*[49m[43mkwargs[49m[43m)[49m
[32m     77[39m [38;5;28;01mreturn[39;00m retval

[36mFile [39m[32m/usr/share/miniconda3/envs/runenv/lib/python3.13/site-packages/sympy/utilities/autowrap.py:1177[39m, in [36mufuncify[39m[34m(args, expr, language, backend, tempdir, flags, verbose, helpers, **kwargs)[39m
[32m   1175[39m args = [y] + indexed_args + [m]
[32m   1176[39m args_with_indices = [a[i] [38;5;28;01mfor[39;00m a [38;5;129;01min[39;00m indexed_args]
[32m-> [39m[32m1177[39m [38;5;28;01mreturn[39;00m [43mautowrap[49m[43m([49m[43mEq[49m[43m([49m[43my[49m[43m[[49m[43mi[49m[43m][49m[43m,[49m[43m [49m[43mf[49m[43m([49m[43m*[49m[43margs_with_indices[49m[43m)[49m[43m)[49m[43m,[49m[43m [49m[43mlanguage[49m[43m,[49m[43m [49m[43mbackend[49m[43m,[49m
[32m   1178[39m [43m                [49m[43mtempdir[49m[43m,[49m[43m [49m[43margs[49m[43m,[49m[43m [49m[43mflags[49m[43m,[49m[43m [49m[43mverbose[49m[43m,[49m[43m [49m[43mhelpers[49m[43m,[49m[43m [49m[43m*[49m[43m*[49m[43mkwargs[49m[43m)[49m

[36mFile [39m[32m/usr/share/miniconda3/envs/runenv/lib/python3.13/site-packages/sympy/core/cache.py:76[39m, in [36m__cacheit.<locals>.func_wrapper.<locals>.wrapper[39m[34m(*args, **kwargs)[39m
[32m     74[39m     [38;5;28;01mif[39;00m [38;5;129;01mnot[39;00m e.args [38;5;129;01mor[39;00m [38;5;129;01mnot[39;00m e.args[[32m0[39m].startswith([33m'[39m[33munhashable type:[39m[33m'[39m):
[32m     75[39m         [38;5;28;01mraise[39;00m
[32m---> [39m[32m76[39m     retval = [43mfunc[49m[43m([49m[43m*[49m[43margs[49m[43m,[49m[43m [49m[43m*[49m[43m*[49m[43mkwargs[49m[43m)[49m
[32m     77[39m [38;5;28;01mreturn[39;00m retval

[36mFile [39m[32m/usr/share/miniconda3/envs/runenv/lib/python3.13/site-packages/sympy/utilities/autowrap.py:690[39m, in [36mautowrap[39m[34m(expr, language, backend, tempdir, args, flags, verbose, helpers, code_gen, **kwargs)[39m
[32m    687[39m         new_args.append(missing.name)
[32m    688[39m     routine = code_gen.routine([33m'[39m[33mautofunc[39m[33m'[39m, expr, args + new_args)
[32m--> [39m[32m690[39m [38;5;28;01mreturn[39;00m [43mcode_wrapper[49m[43m.[49m[43mwrap_code[49m[43m([49m[43mroutine[49m[43m,[49m[43m [49m[43mhelpers[49m[43m=[49m[43mhelps[49m[43m)[49m

[36mFile [39m[32m/usr/share/miniconda3/envs/runenv/lib/python3.13/site-packages/sympy/utilities/autowrap.py:164[39m, in [36mCodeWrapper.wrap_code[39m[34m(self, routine, helpers)[39m
[32m    162[39m     [38;5;28mself[39m._generate_code(routine, helpers)
[32m    163[39m     [38;5;28mself[39m._prepare_files(routine)
[32m--> [39m[32m164[39m     [38;5;28;43mself[39;49m[43m.[49m[43m_process_files[49m[43m([49m[43mroutine[49m[43m)[49m
[32m    165[39m     mod = [38;5;28m__import__[39m([38;5;28mself[39m.module_name)
[32m    166[39m [38;5;28;01mfinally[39;00m:

[36mFile [39m[32m/usr/share/miniconda3/envs/runenv/lib/python3.13/site-packages/sympy/utilities/autowrap.py:185[39m, in [36mCodeWrapper._process_files[39m[34m(self, routine)[39m
[32m    183[39m     retoutput = check_output(command, stderr=STDOUT)
[32m    184[39m [38;5;28;01mexcept[39;00m CalledProcessError [38;5;28;01mas[39;00m e:
[32m--> [39m[32m185[39m     [38;5;28;01mraise[39;00m CodeWrapError(
[32m    186[39m         [33m"[39m[33mError while executing command: [39m[38;5;132;01m%s[39;00m[33m. Command output is:[39m[38;5;130;01m\n[39;00m[38;5;132;01m%s[39;00m[33m"[39m % (
[32m    187[39m             [33m"[39m[33m [39m[33m"[39m.join(command), e.output.decode([33m'[39m[33mutf-8[39m[33m'[39m)))
[32m    188[39m [38;5;28;01mif[39;00m [38;5;129;01mnot[39;00m [38;5;28mself[39m.quiet:
[32m    189[39m     [38;5;28mprint[39m(retoutput)

[31mCodeWrapError[39m: Error while executing command: /usr/share/miniconda3/envs/runenv/bin/python -c import numpy.f2py as f2py2e;f2py2e.main() -c -m wrapper_module_0 wrapped_code_0.f90. Command output is:
Traceback (most recent call last):
  File [35m"<string>"[0m, line [35m1[0m, in [35m<module>[0m
    import numpy.f2py as f2py2e;[31mf2py2e.main[0m[1;31m()[0m
                                [31m~~~~~~~~~~~[0m[1;31m^^[0m
  File [35m"/usr/share/miniconda3/envs/runenv/lib/python3.13/site-packages/numpy/f2py/f2py2e.py"[0m, line [35m781[0m, in [35mmain[0m
    [31mrun_compile[0m[1;31m()[0m
    [31m~~~~~~~~~~~[0m[1;31m^^[0m
  File [35m"/usr/share/miniconda3/envs/runenv/lib/python3.13/site-packages/numpy/f2py/f2py2e.py"[0m, line [35m753[0m, in [35mrun_compile[0m
    [31mbuilder.compile[0m[1;31m()[0m
    [31m~~~~~~~~~~~~~~~[0m[1;31m^^[0m
  File [35m"/usr/share/miniconda3/envs/runenv/lib/python3.13/site-packages/numpy/f2py/_backends/_meson.py"[0m, line [35m192[0m, in [35mcompile[0m
    [31mself.run_meson[0m[1;31m(self.build_dir)[0m
    [31m~~~~~~~~~~~~~~[0m[1;31m^^^^^^^^^^^^^^^^[0m
  File [35m"/usr/share/miniconda3/envs/runenv/lib/python3.13/site-packages/numpy/f2py/_backends/_meson.py"[0m, line [35m185[0m, in [35mrun_meson[0m
    [31mself._run_subprocess_command[0m[1;31m(setup_command, build_dir)[0m
    [31m~~~~~~~~~~~~~~~~~~~~~~~~~~~~[0m[1;31m^^^^^^^^^^^^^^^^^^^^^^^^^^[0m
  File [35m"/usr/share/miniconda3/envs/runenv/lib/python3.13/site-packages/numpy/f2py/_backends/_meson.py"[0m, line [35m181[0m, in [35m_run_subprocess_command[0m
    [31msubprocess.run[0m[1;31m(command, cwd=cwd, check=True)[0m
    [31m~~~~~~~~~~~~~~[0m[1;31m^^^^^^^^^^^^^^^^^^^^^^^^^^^^^^[0m
  File [35m"/usr/share/miniconda3/envs/runenv/lib/python3.13/subprocess.py"[0m, line [35m554[0m, in [35mrun[0m
    with [31mPopen[0m[1;31m(*popenargs, **kwargs)[0m as process:
         [31m~~~~~[0m[1;31m^^^^^^^^^^^^^^^^^^^^^^[0m
  File [35m"/usr/share/miniconda3/envs/runenv/lib/python3.13/subprocess.py"[0m, line [35m1039[0m, in [35m__init__[0m
    [31mself._execute_child[0m[1;31m(args, executable, preexec_fn, close_fds,[0m
    [31m~~~~~~~~~~~~~~~~~~~[0m[1;31m^^^^^^^^^^^^^^^^^^^^^^^^^^^^^^^^^^^^^^^^^[0m
                        [1;31mpass_fds, cwd, env,[0m
                        [1;31m^^^^^^^^^^^^^^^^^^^[0m
    ...<5 lines>...
                        [1;31mgid, gids, uid, umask,[0m
                        [1;31m^^^^^^^^^^^^^^^^^^^^^^[0m
                        [1;31mstart_new_session, process_group)[0m
                        [1;31m^^^^^^^^^^^^^^^^^^^^^^^^^^^^^^^^^[0m
  File [35m"/usr/share/miniconda3/envs/runenv/lib/python3.13/subprocess.py"[0m, line [35m1972[0m, in [35m_execute_child[0m
    raise child_exception_type(errno_num, err_msg, err_filename)
[1;35mFileNotFoundError[0m: [35m[Errno 2] No such file or directory: 'meson'[0m
Cannot use distutils backend with Python>=3.12, using meson backend instead.
Using meson backend
Will pass --lower to f2py
See https://numpy.org/doc/stable/f2py/buildtools/meson.html
Reading fortran codes...
	Reading file 'wrapped_code_0.f90' (format:free)
Post-processing...
	Block: wrapper_module_0
			Block: autofunc
Applying post-processing hooks...
  character_backward_compatibility_hook
Post-processing (stage 2)...
Building modules...
    Building module "wrapper_module_0"...
    Generating possibly empty wrappers"
    Maybe empty "wrapper_module_0-f2pywrappers.f"
        Constructing wrapper function "autofunc"...
          y_3625019 = autofunc(x_3625023,[m_3625020])
    Wrote C/API module "wrapper_module_0" to file "./wrapper_module_0module.c"


