Traceback (most recent call last):
  File "/usr/share/miniconda3/envs/runenv/lib/python3.13/site-packages/jupyter_core/utils/__init__.py", line 154, in wrapped
    asyncio.get_running_loop()
    ~~~~~~~~~~~~~~~~~~~~~~~~^^
RuntimeError: no running event loop

During handling of the above exception, another exception occurred:

Traceback (most recent call last):
  File "/usr/share/miniconda3/envs/runenv/lib/python3.13/site-packages/jupyter_cache/executors/utils.py", line 58, in single_nb_execution
    executenb(
    ~~~~~~~~~^
        nb,
        ^^^
    ...<4 lines>...
        **kwargs,
        ^^^^^^^^^
    )
    ^
  File "/usr/share/miniconda3/envs/runenv/lib/python3.13/site-packages/nbclient/client.py", line 1319, in execute
    return NotebookClient(nb=nb, resources=resources, km=km, **kwargs).execute()
           ~~~~~~~~~~~~~~~~~~~~~~~~~~~~~~~~~~~~~~~~~~~~~~~~~~~~~~~~~~~~~~~~~~~^^
  File "/usr/share/miniconda3/envs/runenv/lib/python3.13/site-packages/jupyter_core/utils/__init__.py", line 158, in wrapped
    return loop.run_until_complete(inner)
           ~~~~~~~~~~~~~~~~~~~~~~~^^^^^^^
  File "/usr/share/miniconda3/envs/runenv/lib/python3.13/asyncio/base_events.py", line 725, in run_until_complete
    return future.result()
           ~~~~~~~~~~~~~^^
  File "/usr/share/miniconda3/envs/runenv/lib/python3.13/site-packages/nbclient/client.py", line 709, in async_execute
    await self.async_execute_cell(
        cell, index, execution_count=self.code_cells_executed + 1
    )
  File "/usr/share/miniconda3/envs/runenv/lib/python3.13/site-packages/nbclient/client.py", line 1062, in async_execute_cell
    await self._check_raise_for_error(cell, cell_index, exec_reply)
  File "/usr/share/miniconda3/envs/runenv/lib/python3.13/site-packages/nbclient/client.py", line 918, in _check_raise_for_error
    raise CellExecutionError.from_cell_and_msg(cell, exec_reply_content)
nbclient.exceptions.CellExecutionError: An error occurred while executing the following cell:
------------------
a = np.linspace(0, 1+1j, 6)
f(a, a)
------------------


[31m---------------------------------------------------------------------------[39m
[31mTypeError[39m                                 Traceback (most recent call last)
[36mCell[39m[36m [39m[32mIn[25][39m[32m, line 2[39m
[32m      1[39m a = np.linspace([32m0[39m, [32m1[39m+[32m1[39mj, [32m6[39m)
[32m----> [39m[32m2[39m [43mf[49m[43m([49m[43ma[49m[43m,[49m[43m [49m[43ma[49m[43m)[49m

[36mFile [39m[32m/usr/share/miniconda3/envs/runenv/lib/python3.13/site-packages/numba/np/ufunc/dufunc.py:288[39m, in [36mDUFunc.__call__[39m[34m(self, *args, **kws)[39m
[32m    286[39m             [38;5;28;01mreturn[39;00m output
[32m    287[39m [38;5;28;01melse[39;00m:
[32m--> [39m[32m288[39m     [38;5;28;01mreturn[39;00m [38;5;28;43msuper[39;49m[43m([49m[43m)[49m[43m.[49m[34;43m__call__[39;49m[43m([49m[43m*[49m[43margs[49m[43m,[49m[43m [49m[43m*[49m[43m*[49m[43mkws[49m[43m)[49m

[31mTypeError[39m: ufunc 'f' not supported for the input types, and the inputs could not be safely coerced to any supported types according to the casting rule ''safe''

