Traceback (most recent call last):
  File "/usr/share/miniconda3/envs/runenv/lib/python3.10/site-packages/jupyter_cache/executors/utils.py", line 51, in single_nb_execution
    executenb(
  File "/usr/share/miniconda3/envs/runenv/lib/python3.10/site-packages/nbclient/client.py", line 1204, in execute
    return NotebookClient(nb=nb, resources=resources, km=km, **kwargs).execute()
  File "/usr/share/miniconda3/envs/runenv/lib/python3.10/site-packages/nbclient/util.py", line 84, in wrapped
    return just_run(coro(*args, **kwargs))
  File "/usr/share/miniconda3/envs/runenv/lib/python3.10/site-packages/nbclient/util.py", line 62, in just_run
    return loop.run_until_complete(coro)
  File "/usr/share/miniconda3/envs/runenv/lib/python3.10/asyncio/base_events.py", line 649, in run_until_complete
    return future.result()
  File "/usr/share/miniconda3/envs/runenv/lib/python3.10/site-packages/nbclient/client.py", line 663, in async_execute
    await self.async_execute_cell(
  File "/usr/share/miniconda3/envs/runenv/lib/python3.10/site-packages/nbclient/client.py", line 965, in async_execute_cell
    await self._check_raise_for_error(cell, cell_index, exec_reply)
  File "/usr/share/miniconda3/envs/runenv/lib/python3.10/site-packages/nbclient/client.py", line 862, in _check_raise_for_error
    raise CellExecutionError.from_cell_and_msg(cell, exec_reply_content)
nbclient.exceptions.CellExecutionError: An error occurred while executing the following cell:
------------------
a = np.linspace(0, 1+1j, 6)
f(a, a)
------------------

[0;31m---------------------------------------------------------------------------[0m
[0;31mTypeError[0m                                 Traceback (most recent call last)
Cell [0;32mIn[25], line 2[0m
[1;32m      1[0m a [38;5;241m=[39m np[38;5;241m.[39mlinspace([38;5;241m0[39m, [38;5;241m1[39m[38;5;241m+[39m[38;5;241m1[39mj, [38;5;241m6[39m)
[0;32m----> 2[0m [43mf[49m[43m([49m[43ma[49m[43m,[49m[43m [49m[43ma[49m[43m)[49m

[0;31mTypeError[0m: ufunc 'f' not supported for the input types, and the inputs could not be safely coerced to any supported types according to the casting rule ''safe''
TypeError: ufunc 'f' not supported for the input types, and the inputs could not be safely coerced to any supported types according to the casting rule ''safe''

